output/market_data_spot_BTCUSDT.csv
recv_tsec,recv_tnsec,venue,stream_kind,shard_id,conn_epoch,conn_seq,symbol,payload_json
1780741408|310748000|spot|depth|0|0|0|BTCUSDT|"{""lastUpdateId"":95181576652,""bids"":[[""60671.98000000"",""0.88093000""],[""60671.97000000"",""0.00035000""],[""60671.96000000"",""0.00017000""],[""60671.85000000"",""0.00009000""],[""60670.62000000"",""0.00009000""]],""asks"":[[""60671.99000000"",""1.54956000""],[""60672.00000000"",""0.02353000""],[""60672.01000000"",""0.00017000""],[""60673.01000000"",""0.00040000""],[""60673.08000000"",""0.00010000""]]}"
1780741408|310856000|spot|depth|0|0|1|BTCUSDT|"{""e"":""depthUpdate"",""E"":1780741408414,""s"":""BTCUSDT"",""U"":95181576547,""u"":95181576652,""b"":[[""60671.98000000"",""0.88093000""],[""60670.12000000"",""0.00018000""],[""60670.11000000"",""0.09825000""],[""60668.63000000"",""0.22934000""],[""60668.25000000"",""0.00018000""],[""60668.24000000"",""0.10400000""],[""60667.11000000"",""0.33013000""],[""60666.50000000"",""0.49506000""],[""60666.38000000"",""0.00000000""],[""60666.02000000"",""0.00000000""],[""60666.01000000"",""0.10418000""],[""60665.91000000"",""0.27300000""],[""60664.71000000"",""1.48735000""],[""60663.99000000"",""0.17824000""],[""60663.88000000"",""0.16509000""],[""60663.83000000"",""0.00000000""],[""60662.63000000"",""0.10400000""],[""60662.18000000"",""0.10380000""],[""60659.21000000"",""0.00009000""],[""60635.57000000"",""0.01109000""],[""60580.78000000"",""0.09904000""],[""60540.03000000"",""0.08525000""],[""54604.79000000"",""0.00450000""]],""a"":[[""60671.99000000"",""1.54956000""],[""60672.00000000"",""0.02353000""],[""60673.09000000"",""0.00018000""],[""60673.84000000"",""0.00018000""],[""60673.85000000"",""0.07059000""],[""60673.99000000"",""0.00009000""],[""60676.97000000"",""0.01803000""],[""60679.60000000"",""0.00000000""],[""60681.18000000"",""0.00000000""],[""60683.49000000"",""0.00009000""],[""60685.05000000"",""0.58383000""],[""60685.06000000"",""1.48717000""],[""60685.07000000"",""0.00000000""],[""60690.67000000"",""0.00000000""],[""60692.56000000"",""0.00000000""],[""60693.34000000"",""0.00000000""],[""60708.40000000"",""0.00441000""],[""60729.21000000"",""0.00000000""],[""60729.24000000"",""0.00000000""],[""60732.06000000"",""0.00000000""],[""60851.75000000"",""0.00000000""],[""60882.21000000"",""0.01971000""]]}"
1780741408|409550000|spot|depth|0|0|2|BTCUSDT|"{""lastUpdateId"":95181576736,""bids"":[[""60671.98000000"",""0.81716000""],[""60671.97000000"",""0.00035000""],[""60671.96000000"",""0.00017000""],[""60671.85000000"",""0.00009000""],[""60670.62000000"",""0.00009000""]],""asks"":[[""60671.99000000"",""1.54938000""],[""60672.00000000"",""0.02335000""],[""60672.01000000"",""0.00017000""],[""60672.83000000"",""0.00841000""],[""60673.01000000"",""0.00040000""]]}"
1780741408|409557000|spot|depth|0|0|3|BTCUSDT|"{""e"":""depthUpdate"",""E"":1780741408514,""s"":""BTCUSDT"",""U"":95181576653,""u"":95181576736,""b"":[[""60671.98000000"",""0.81716000""],[""60670.12000000"",""0.00000000""],[""60670.11000000"",""0.00018000""],[""60668.63000000"",""0.22934000""],[""60668.25000000"",""0.00000000""],[""60668.24000000"",""0.00027000""],[""60668.00000000"",""0.04142000""],[""60667.12000000"",""0.00018000""],[""60667.11000000"",""0.00027000""],[""60666.51000000"",""0.00009000""],[""60666.50000000"",""0.00018000""],[""60666.01000000"",""0.00009000""],[""60665.91000000"",""0.00300000""],[""60664.72000000"",""0.10391000""],[""60664.71000000"",""1.48717000""],[""60663.99000000"",""0.17806000""],[""60663.88000000"",""0.16482000""],[""60662.63000000"",""0.00000000""],[""60662.18000000"",""0.00000000""],[""60660.39000000"",""0.16027000""],[""54604.79000000"",""0.00490000""],[""48537.59000000"",""0.00087000""]],""a"":[[""60671.99000000"",""1.54938000""],[""60672.00000000"",""0.02335000""],[""60672.83000000"",""0.00841000""],[""60673.09000000"",""0.00000000""],[""60673.10000000"",""0.00000000""],[""60673.99000000"",""0.00018000""],[""60675.72000000"",""0.00000000""],[""60729.31000000"",""0.00000000""],[""60732.29000000"",""0.03000000""],[""60824.75000000"",""0.00000000""],[""60857.91000000"",""0.01971000""],[""86258.81000000"",""0.00028000""]]}"
1780741408|514261000|spot|depth|0|0|4|BTCUSDT|"{""lastUpdateId"":95181576820,""bids"":[[""60671.98000000"",""0.88533000""],[""60671.97000000"",""0.00035000""],[""60671.96000000"",""0.00017000""],[""60671.85000000"",""0.00009000""],[""60670.62000000"",""0.00009000""]],""asks"":[[""60671.99000000"",""1.54938000""],[""60672.00000000"",""0.02335000""],[""60672.01000000"",""0.00017000""],[""60672.83000000"",""0.00841000""],[""60673.01000000"",""0.00040000""]]}"
1780741408|514268000|spot|depth|0|0|5|BTCUSDT|"{""e"":""depthUpdate"",""E"":1780741408614,""s"":""BTCUSDT"",""U"":95181576737,""u"":95181576820,""b"":[[""60671.98000000"",""0.88533000""],[""60670.12000000"",""0.00018000""],[""60670.11000000"",""0.10391000""],[""60668.63000000"",""0.22934000""],[""60668.25000000"",""0.00018000""],[""60668.24000000"",""0.10391000""],[""60668.00000000"",""0.04142000""],[""60667.18000000"",""0.00059000""],[""60667.12000000"",""0.00000000""],[""60667.11000000"",""0.00000000""],[""60666.51000000"",""0.00000000""],[""60666.50000000"",""0.00000000""],[""60666.38000000"",""0.00000000""],[""60666.37000000"",""0.10427000""],[""60665.91000000"",""0.27300000""],[""60664.73000000"",""0.00000000""],[""60664.72000000"",""0.10409000""],[""60664.71000000"",""1.48735000""],[""60663.99000000"",""0.17833000""],[""60663.91000000"",""0.18349000""],[""60663.88000000"",""0.16518000""],[""60663.42000000"",""0.00817000""],[""60662.63000000"",""0.10391000""],[""60662.18000000"",""0.10391000""],[""60661.73000000"",""0.00000000""],[""60661.16000000"",""0.00000000""],[""60660.39000000"",""0.00000000""],[""60659.12000000"",""0.00000000""],[""60641.65000000"",""0.00000000""],[""60532.01000000"",""0.00000000""],[""60523.50000000"",""0.00976000""],[""54604.79000000"",""0.00490000""],[""54604.00000000"",""0.00301000""],[""48537.59000000"",""0.00046000""]],""a"":[[""60675.72000000"",""0.00009000""],[""60685.05000000"",""0.13991000""],[""60685.06000000"",""0.00000000""],[""60708.40000000"",""0.01060000""],[""60721.34000000"",""0.00000000""],[""60728.59000000"",""0.00017000""],[""60729.29000000"",""0.00000000""],[""60732.36000000"",""0.00000000""],[""60763.99000000"",""0.02034000""],[""60764.75000000"",""0.01974000""]]}"
1780741408|608874000|spot|depth|0|0|6|BTCUSDT|"{""lastUpdateId"":95181576962,""bids"":[[""60671.98000000"",""1.83078000""],[""60671.97000000"",""0.00035000""],[""60671.96000000"",""0.00017000""],[""60671.85000000"",""0.00009000""],[""60671.34000000"",""0.05349000""]],""asks"":[[""60671.99000000"",""1.32910000""],[""60672.00000000"",""0.02353000""],[""60672.01000000"",""0.00017000""],[""60673.01000000"",""0.00040000""],[""60673.08000000"",""0.00010000""]]}"
1780741408|608885000|spot|depth|0|0|7|BTCUSDT|"{""e"":""depthUpdate"",""E"":1780741408714,""s"":""BTCUSDT"",""U"":95181576821,""u"":95181576962,""b"":[[""60671.98000000"",""1.83078000""],[""60671.34000000"",""0.05349000""],[""60670.11000000"",""0.10409000""],[""60668.85000000"",""0.00018000""],[""60668.84000000"",""0.00027000""],[""60668.64000000"",""0.15541000""],[""60668.63000000"",""0.00027000""],[""60668.25000000"",""0.00000000""],[""60668.24000000"",""0.10418000""],[""60668.02000000"",""0.14381000""],[""60668.01000000"",""0.00000000""],[""60666.57000000"",""0.00212000""],[""60666.37000000"",""0.10427000""],[""60665.91000000"",""0.27318000""],[""60664.74000000"",""1.26816000""],[""60664.73000000"",""2.31413000""],[""60664.71000000"",""1.48717000""],[""60663.99000000"",""0.17806000""],[""60663.91000000"",""0.00000000""],[""60663.88000000"",""0.16491000""],[""60662.63000000"",""0.10400000""],[""60662.18000000"",""0.10391000""],[""60656.77000000"",""0.02000000""],[""60649.26000000"",""0.00000000""],[""60636.24000000"",""0.00000000""],[""60635.57000000"",""0.00000000""],[""60632.00000000"",""0.01500000""],[""60630.00000000"",""0.01509000""],[""60483.21000000"",""0.00000000""],[""55777.18000000"",""0.00000000""],[""54604.79000000"",""0.00490000""],[""54604.00000000"",""0.00281000""]],""a"":[[""60671.99000000"",""1.32910000""],[""60672.00000000"",""0.02353000""],[""60672.83000000"",""0.00000000""],[""60673.84000000"",""0.00000000""],[""60673.85000000"",""0.00000000""],[""60673.86000000"",""0.00000000""],[""60675.03000000"",""0.00000000""],[""60675.72000000"",""0.00000000""],[""60675.73000000"",""0.00000000""],[""60675.99000000"",""0.00027000""],[""60676.48000000"",""0.00018000""],[""60676.97000000"",""0.00000000""],[""60677.09000000"",""0.00009000""],[""60678.03000000"",""0.00000000""],[""60680.23000000"",""0.01803000""],[""60681.83000000"",""0.02000000""],[""60687.79000000"",""0.00000000""],[""60687.91000000"",""0.40437000""],[""60687.92000000"",""0.00000000""],[""60687.95000000"",""2.31413000""],[""60695.29000000"",""0.00000000""],[""60697.30000000"",""0.00282000""],[""60702.87000000"",""0.50004000""],[""60708.92000000"",""0.01545000""],[""60719.61000000"",""1.63117000""],[""60731.67000000"",""0.00333000""],[""60732.29000000"",""0.00000000""],[""60760.93000000"",""0.04368000""],[""60797.52000000"",""0.00000000""],[""60880.45000000"",""0.05495000""],[""86750.04000000"",""0.00020000""]]}"
